Workbook

Sheet Executive Summary
A1: Chronic Care Cascade Pilot — Cost Model Overview
A3: Pilot purpose
A4: Demonstrate that a trusted intermediary can reuse existing standards-based clinical data and infrastructure to produce a governed diabetes dataset for state public health surveillance and CMS-aligned digital quality measurement, while reducing duplicative reporting and making data quality transparent.
A8: What one modeled pilot site includes | D8: Key modeling boundaries
A9: Primary participant | B9: 1 state PHA | D9: Included | E9: Participant labor, vendor fees, ODCs, participant indirects, site evaluation support, 7.5% contingency
A10: Provider participants | B10: 10 FQHCs and 2 other outpatient healthcare organizations | D10: Excluded | E10: Pre-award charter development, NP/prime administration, independent evaluation, post-pilot operations
A11: Technical diversity | B11: 5 source-system/vendor configurations; 2 shared FQHC configurations | D11: Infrastructure posture | E11: Existing interfaces, platforms, matching, trust, de-identification, monitoring, and analytics are configured—not rebuilt
A12: Intermediary structure | B12: One of three models defined on the Scenario Definitions sheet | D12: Optional add-ons | E12: UDS+ interface; chronic-care referral analysis; new medication-dispensing connection
A13: Core outputs | B13: PHA diabetes surveillance product and CMS122 | D13: Primary user | E13: State PHA; other federal and quality uses are secondary to the site cost build
A14: Operating window | B14: 12-month funded pilot with 9 months of live exchange (6-month sensitivity) | D14: Clinical scope | E14: Diabetes, priced as narrow A1c-focused and broad longitudinal cascade variants
A16: How to use this workbook
A17: 1 | B17: Select the target scenario (intermediary model and dataset scope) on the "Scenario Definitions" sheet.
A18: 2 | B18: Adjust cost-sensitive quantities and assumptions on the "Assumptions & Inputs" sheet.
A20: Source basis: Chronic Pilot Overview; Draft Chronic Care Cascade Pilot Data Flow Architectures; Tech Brief: PHIG B4 Chronic Care Cascade Pilot; and the approved scope assumptions developed for this cost model.
A23: Estimate maturity: provisional bottom-up model. Labor rates, unit hours, vendor fees, participant indirect rates, and benchmark citations require validation before use as a procurement or funding commitment.
A27: Pro Forma Cost Summary
A29: Selected Scenario | B29: Estimating Case | C29: Low | D29: Base | E29: High
A30: ='Scenario Definitions'!C5 -> 2A | B30: =_xlfn.XLOOKUP($A$30, ScenarioTable[Scenario ID], ScenarioTable[Intermediary Model]) -> HIE/HDU with HCCN | C30: =SUMIF('Cost Build-Up'!$AE$5:$AE$77,1,'Cost Build-Up'!$BH$5:$BH$77)+SUM('Optional Add-Ons Build-Up'!$W$5:$W$16) -> 1492378.3 | D30: =SUMIF('Cost Build-Up'!$AE$5:$AE$77,1,'Cost Build-Up'!$BI$5:$BI$77)+SUM('Optional Add-Ons Build-Up'!$X$5:$X$16) -> 3094276.4 | E30: =SUMIF('Cost Build-Up'!$AE$5:$AE$77,1,'Cost Build-Up'!$BJ$5:$BJ$77)+SUM('Optional Add-Ons Build-Up'!$Y$5:$Y$16) -> 8028489.6
B32: Metric | C32: Low | D32: Base | E32: High
B33: Sponsor-funded cost before contingency | C33: =SUMIF('Cost Build-Up'!$AE$5:$AE$77,1,'Cost Build-Up'!$AT$5:$AT$77)+SUMIF('Cost Build-Up'!$AE$5:$AE$77,1,'Cost Build-Up'!$AW$5:$AW$77)+SUMIF('Cost Build-Up'!$AE$5:$AE$77,1,'Cost Build-Up'!$BA$5:$BA$77) -> 1433402 | D33: =SUMIF('Cost Build-Up'!$AE$5:$AE$77,1,'Cost Build-Up'!$AU$5:$AU$77)+SUMIF('Cost Build-Up'!$AE$5:$AE$77,1,'Cost Build-Up'!$AX$5:$AX$77)+SUMIF('Cost Build-Up'!$AE$5:$AE$77,1,'Cost Build-Up'!$BB$5:$BB$77) -> 2911271.7 | E33: =SUMIF('Cost Build-Up'!$AE$5:$AE$77,1,'Cost Build-Up'!$AV$5:$AV$77)+SUMIF('Cost Build-Up'!$AE$5:$AE$77,1,'Cost Build-Up'!$AY$5:$AY$77)+SUMIF('Cost Build-Up'!$AE$5:$AE$77,1,'Cost Build-Up'!$BC$5:$BC$77) -> 7123349.3
B34: Contingency | C34: =SUMIF('Cost Build-Up'!$AE$5:$AE$77,1,'Cost Build-Up'!$BE$5:$BE$77) -> 58976.25 | D34: =SUMIF('Cost Build-Up'!$AE$5:$AE$77,1,'Cost Build-Up'!$BF$5:$BF$77) -> 183004.65 | E34: =SUMIF('Cost Build-Up'!$AE$5:$AE$77,1,'Cost Build-Up'!$BG$5:$BG$77) -> 905140.28
B35: Sponsor-funded cost including contingency | C35: =C33+C34+SUM('Optional Add-Ons Build-Up'!$W$5:$W$16) -> 1492378.3 | D35: =D33+D34+SUM('Optional Add-Ons Build-Up'!$X$5:$X$16) -> 3094276.4 | E35: =E33+E34+SUM('Optional Add-Ons Build-Up'!$Y$5:$Y$16) -> 8028489.6
B36: Unreimbursed in-kind cost | C36: 0 | D36: 0 | E36: 0
B37: Total economic cost | C37: =C35+C36 -> 1492378.3 | D37: =D35+D36 -> 3094276.4 | E37: =E35+E36 -> 8028489.6
B38: One-time implementation and evaluation | C38: =SUMIFS('Cost Build-Up'!$BH$5:$BH$77,'Cost Build-Up'!$D$5:$D$77,"<>Pilot operations and support",'Cost Build-Up'!$AE$5:$AE$77,1) -> 1141936.3 | D38: =SUMIFS('Cost Build-Up'!$BI$5:$BI$77,'Cost Build-Up'!$D$5:$D$77,"<>Pilot operations and support",'Cost Build-Up'!$AE$5:$AE$77,1) -> 2320041.1 | E38: =SUMIFS('Cost Build-Up'!$BJ$5:$BJ$77,'Cost Build-Up'!$D$5:$D$77,"<>Pilot operations and support",'Cost Build-Up'!$AE$5:$AE$77,1) -> 6429867.6
B39: Recurring pilot operations | C39: =SUMIFS('Cost Build-Up'!$BH$5:$BH$77,'Cost Build-Up'!$D$5:$D$77,"Pilot operations and support",'Cost Build-Up'!$AE$5:$AE$77,1) -> 350442 | D39: =SUMIFS('Cost Build-Up'!$BI$5:$BI$77,'Cost Build-Up'!$D$5:$D$77,"Pilot operations and support",'Cost Build-Up'!$AE$5:$AE$77,1) -> 774235.25 | E39: =SUMIFS('Cost Build-Up'!$BJ$5:$BJ$77,'Cost Build-Up'!$D$5:$D$77,"Pilot operations and support",'Cost Build-Up'!$AE$5:$AE$77,1) -> 1598622
B40: Monthly pilot operating run rate | C40: =IFERROR(C39/VLOOKUP("IN-18",'Assumptions & Inputs'!$A$31:$F$69,3,FALSE),0) -> 58407 | D40: =IFERROR(D39/VLOOKUP("IN-18",'Assumptions & Inputs'!$A$31:$F$69,4,FALSE),0) -> 86026.139 | E40: =IFERROR(E39/VLOOKUP("IN-18",'Assumptions & Inputs'!$A$31:$F$69,5,FALSE),0) -> 177624.67
B42: Organization Group | C42: Low | D42: Base | E42: High
B43: State PHA | C43: =SUMIFS('Cost Build-Up'!$BH$5:$BH$77,'Cost Build-Up'!$C$5:$C$77,$B43,'Cost Build-Up'!$AE$5:$AE$77,1) -> 212139.9 | D43: =SUMIFS('Cost Build-Up'!$BI$5:$BI$77,'Cost Build-Up'!$C$5:$C$77,$B43,'Cost Build-Up'!$AE$5:$AE$77,1) -> 375621.1 | E43: =SUMIFS('Cost Build-Up'!$BJ$5:$BJ$77,'Cost Build-Up'!$C$5:$C$77,$B43,'Cost Build-Up'!$AE$5:$AE$77,1) -> 927010.2
B44: HIE/HDU Intermediary | C44: =SUMIFS('Cost Build-Up'!$BH$5:$BH$77,'Cost Build-Up'!$C$5:$C$77,$B44,'Cost Build-Up'!$AE$5:$AE$77,1) -> 788159.4 | D44: =SUMIFS('Cost Build-Up'!$BI$5:$BI$77,'Cost Build-Up'!$C$5:$C$77,$B44,'Cost Build-Up'!$AE$5:$AE$77,1) -> 1523946.9 | E44: =SUMIFS('Cost Build-Up'!$BJ$5:$BJ$77,'Cost Build-Up'!$C$5:$C$77,$B44,'Cost Build-Up'!$AE$5:$AE$77,1) -> 3568234
B45: HCCN | C45: =SUMIFS('Cost Build-Up'!$BH$5:$BH$77,'Cost Build-Up'!$C$5:$C$77,$B45,'Cost Build-Up'!$AE$5:$AE$77,1) -> 262464.22 | D45: =SUMIFS('Cost Build-Up'!$BI$5:$BI$77,'Cost Build-Up'!$C$5:$C$77,$B45,'Cost Build-Up'!$AE$5:$AE$77,1) -> 578428.5 | E45: =SUMIFS('Cost Build-Up'!$BJ$5:$BJ$77,'Cost Build-Up'!$C$5:$C$77,$B45,'Cost Build-Up'!$AE$5:$AE$77,1) -> 1484093.5
B46: Healthcare Organizations & FQHCs | C46: =SUMIFS('Cost Build-Up'!$BH$5:$BH$77,'Cost Build-Up'!$C$5:$C$77,$B46,'Cost Build-Up'!$AE$5:$AE$77,1) -> 229614.75 | D46: =SUMIFS('Cost Build-Up'!$BI$5:$BI$77,'Cost Build-Up'!$C$5:$C$77,$B46,'Cost Build-Up'!$AE$5:$AE$77,1) -> 616279.85 | E46: =SUMIFS('Cost Build-Up'!$BJ$5:$BJ$77,'Cost Build-Up'!$C$5:$C$77,$B46,'Cost Build-Up'!$AE$5:$AE$77,1) -> 2049151.9
B48: Lifecycle Workstream | C48: Low | D48: Base | E48: High
B49: Implementation management | C49: =SUMIFS('Cost Build-Up'!$BH$5:$BH$77,'Cost Build-Up'!$D$5:$D$77,$B49,'Cost Build-Up'!$AE$5:$AE$77,1) -> 202089 | D49: =SUMIFS('Cost Build-Up'!$BI$5:$BI$77,'Cost Build-Up'!$D$5:$D$77,$B49,'Cost Build-Up'!$AE$5:$AE$77,1) -> 303779 | E49: =SUMIFS('Cost Build-Up'!$BJ$5:$BJ$77,'Cost Build-Up'!$D$5:$D$77,$B49,'Cost Build-Up'!$AE$5:$AE$77,1) -> 610476
B50: Governance, legal, privacy, and security | C50: =SUMIFS('Cost Build-Up'!$BH$5:$BH$77,'Cost Build-Up'!$D$5:$D$77,$B50,'Cost Build-Up'!$AE$5:$AE$77,1) -> 150347.4 | D50: =SUMIFS('Cost Build-Up'!$BI$5:$BI$77,'Cost Build-Up'!$D$5:$D$77,$B50,'Cost Build-Up'!$AE$5:$AE$77,1) -> 307886.7 | E50: =SUMIFS('Cost Build-Up'!$BJ$5:$BJ$77,'Cost Build-Up'!$D$5:$D$77,$B50,'Cost Build-Up'!$AE$5:$AE$77,1) -> 1106709.2
B51: Data specification and mapping | C51: =SUMIFS('Cost Build-Up'!$BH$5:$BH$77,'Cost Build-Up'!$D$5:$D$77,$B51,'Cost Build-Up'!$AE$5:$AE$77,1) -> 92238.075 | D51: =SUMIFS('Cost Build-Up'!$BI$5:$BI$77,'Cost Build-Up'!$D$5:$D$77,$B51,'Cost Build-Up'!$AE$5:$AE$77,1) -> 191686.25 | E51: =SUMIFS('Cost Build-Up'!$BJ$5:$BJ$77,'Cost Build-Up'!$D$5:$D$77,$B51,'Cost Build-Up'!$AE$5:$AE$77,1) -> 483784.3
B52: Configuration and integration | C52: =SUMIFS('Cost Build-Up'!$BH$5:$BH$77,'Cost Build-Up'!$D$5:$D$77,$B52,'Cost Build-Up'!$AE$5:$AE$77,1) -> 379185.15 | D52: =SUMIFS('Cost Build-Up'!$BI$5:$BI$77,'Cost Build-Up'!$D$5:$D$77,$B52,'Cost Build-Up'!$AE$5:$AE$77,1) -> 734896.25 | E52: =SUMIFS('Cost Build-Up'!$BJ$5:$BJ$77,'Cost Build-Up'!$D$5:$D$77,$B52,'Cost Build-Up'!$AE$5:$AE$77,1) -> 1790295.9
B53: Testing and remediation | C53: =SUMIFS('Cost Build-Up'!$BH$5:$BH$77,'Cost Build-Up'!$D$5:$D$77,$B53,'Cost Build-Up'!$AE$5:$AE$77,1) -> 149182.27 | D53: =SUMIFS('Cost Build-Up'!$BI$5:$BI$77,'Cost Build-Up'!$D$5:$D$77,$B53,'Cost Build-Up'!$AE$5:$AE$77,1) -> 391268.4 | E53: =SUMIFS('Cost Build-Up'!$BJ$5:$BJ$77,'Cost Build-Up'!$D$5:$D$77,$B53,'Cost Build-Up'!$AE$5:$AE$77,1) -> 1262982.1
B54: Onboarding and training | C54: =SUMIFS('Cost Build-Up'!$BH$5:$BH$77,'Cost Build-Up'!$D$5:$D$77,$B54,'Cost Build-Up'!$AE$5:$AE$77,1) -> 45847.125 | D54: =SUMIFS('Cost Build-Up'!$BI$5:$BI$77,'Cost Build-Up'!$D$5:$D$77,$B54,'Cost Build-Up'!$AE$5:$AE$77,1) -> 124268.5 | E54: =SUMIFS('Cost Build-Up'!$BJ$5:$BJ$77,'Cost Build-Up'!$D$5:$D$77,$B54,'Cost Build-Up'!$AE$5:$AE$77,1) -> 372939
B55: Pilot operations and support | C55: =SUMIFS('Cost Build-Up'!$BH$5:$BH$77,'Cost Build-Up'!$D$5:$D$77,$B55,'Cost Build-Up'!$AE$5:$AE$77,1) -> 350442 | D55: =SUMIFS('Cost Build-Up'!$BI$5:$BI$77,'Cost Build-Up'!$D$5:$D$77,$B55,'Cost Build-Up'!$AE$5:$AE$77,1) -> 774235.25 | E55: =SUMIFS('Cost Build-Up'!$BJ$5:$BJ$77,'Cost Build-Up'!$D$5:$D$77,$B55,'Cost Build-Up'!$AE$5:$AE$77,1) -> 1598622
...

Sheet Scenario Definitions
A1: Scenario Definitions
A2: Scenario convention: the letter identifies dataset scope (A = narrow A1c-focused; B = broad longitudinal cascade). The number identifies the intermediary operating model.
B5: Selected Scenario | C5: 2A
A7: Scenario ID | B7: Intermediary Model | C7: Provider Structure | D7: Dataset Scope | E7: Operations | F7: Key Distinction | G7: Low Total | H7: Base Total | I7: High Total
A8: 1A | B8: HIE/HDU without HCCN | C8: 10 FQHCs + 2 healthcare organizations connect without HCCN consolidation | D8: Narrow A1c-focused | E8: 9 months | F8: Most source connections; no HCCN managed-services layer | G8: =SUM('Cost Build-Up'!$BU$5:$BU$77) -> 1229914.1 | H8: =SUM('Cost Build-Up'!$BV$5:$BV$77) -> 2587667.9 | I8: =SUM('Cost Build-Up'!$BW$5:$BW$77) -> 6714496.1
A9: 1B | B9: HIE/HDU without HCCN | C9: Same as 1A | D9: Broad longitudinal diabetes cascade | E9: 9 months | F9: Adds broader data, mapping, analytics, and validation | G9: =SUM('Cost Build-Up'!$BX$5:$BX$77) -> 1285904.6 | H9: =SUM('Cost Build-Up'!$BY$5:$BY$77) -> 2702027.9 | I9: =SUM('Cost Build-Up'!$BZ$5:$BZ$77) -> 7013848.6
A10: 2A | B10: HIE/HDU with HCCN | C10: HCCN consolidates 10 FQHCs; 2 healthcare organizations connect directly | D10: Narrow A1c-focused | E10: 9 months | F10: HCCN adds managed services and reduces production interfaces | G10: =SUM('Cost Build-Up'!$CA$5:$CA$77) -> 1492378.3 | H10: =SUM('Cost Build-Up'!$CB$5:$CB$77) -> 3094276.4 | I10: =SUM('Cost Build-Up'!$CC$5:$CC$77) -> 8028489.6
A11: 2B | B11: HIE/HDU with HCCN | C11: Same as 2A | D11: Broad longitudinal diabetes cascade | E11: 9 months | F11: Broad scope plus two intermediary/aggregation layers | G11: =SUM('Cost Build-Up'!$CD$5:$CD$77) -> 1548368.8 | H11: =SUM('Cost Build-Up'!$CE$5:$CE$77) -> 3208636.4 | I11: =SUM('Cost Build-Up'!$CF$5:$CF$77) -> 8327842.1
A12: 3A | B12: HCCN acting as intermediary | C12: HCCN ingests 10 FQHCs and 2 healthcare organizations; no HIE/HDU | D12: Narrow A1c-focused | E12: 9 months | F12: HCCN performs full intermediary, trust, and PHA delivery functions | G12: =SUM('Cost Build-Up'!$CG$5:$CG$77) -> 977031.38 | H12: =SUM('Cost Build-Up'!$CH$5:$CH$77) -> 2187904.5 | I12: =SUM('Cost Build-Up'!$CI$5:$CI$77) -> 5846278.1
A13: 3B | B13: HCCN acting as intermediary | C13: Same as 3A | D13: Broad longitudinal diabetes cascade | E13: 9 months | F13: Broad scope delivered entirely through HCCN intermediary model | G13: =SUM('Cost Build-Up'!$CJ$5:$CJ$77) -> 1033021.9 | H13: =SUM('Cost Build-Up'!$CK$5:$CK$77) -> 2302264.5 | I13: =SUM('Cost Build-Up'!$CL$5:$CL$77) -> 6145630.6
A15: Separately priced add-ons and sensitivities
A16: These packages are excluded from the base scenario unless their trigger occurs.
A18: Add-On ID | B18: Item | C18: Trigger | D18: Applies To | E18: Model Treatment | F18: Key Cost Driver | G18: Low Total | H18: Base Total | I18: High Total
A19: ADD-01 | B19: UDS+ interface | C19: Charter includes UDS+ and no adequate existing pathway is available | D19: Any scenario | E19: Optional add-on | F19: May require a new interface, mapping, authentication, and HRSA validation | G19: =SUM('Optional Add-Ons Build-Up'!M5, 'Optional Add-Ons Build-Up'!P5) -> 170000 | H19: =SUM('Optional Add-Ons Build-Up'!N5, 'Optional Add-Ons Build-Up'!Q5) -> 370000 | I19: =SUM('Optional Add-Ons Build-Up'!O5, 'Optional Add-Ons Build-Up'!R5) -> 750000
A20: ADD-02 | B20: Closed-loop chronic-care referral analysis | C20: Charter includes referral add-on and an existing referral platform/governance model is operational | D20: Any scenario with existing referral infrastructure | E20: Optional add-on | F20: Marginal workflow, data, and evaluation configuration only | G20: =SUM('Optional Add-Ons Build-Up'!M6, 'Optional Add-Ons Build-Up'!P6) -> 60000 | H20: =SUM('Optional Add-Ons Build-Up'!N6, 'Optional Add-Ons Build-Up'!Q6) -> 135000 | I20: =SUM('Optional Add-Ons Build-Up'!O6, 'Optional Add-Ons Build-Up'!R6) -> 320000
A21: ADD-03 | B21: New medication-dispensing connection | C21: Broad scope requires dispensing data not already available | D21: Broad-scope scenarios if existing data are unavailable | E21: Optional add-on | F21: New pharmacy/payer interface and data-use work | G21: =SUM('Optional Add-Ons Build-Up'!M7, 'Optional Add-Ons Build-Up'!P7) -> 175000 | H21: =SUM('Optional Add-Ons Build-Up'!N7, 'Optional Add-Ons Build-Up'!Q7) -> 420000 | I21: =SUM('Optional Add-Ons Build-Up'!O7, 'Optional Add-Ons Build-Up'!R7) -> 950000
A22: ADD-04 | B22: Additional non-FQHC healthcare organization | C22: Participant count exceeds two | D22: Any scenario | E22: Marginal unit | F22: Onboarding, legal, validation, training, and support | G22: =SUM('Optional Add-Ons Build-Up'!M8, 'Optional Add-Ons Build-Up'!P8) -> 30000 | H22: =SUM('Optional Add-Ons Build-Up'!N8, 'Optional Add-Ons Build-Up'!Q8) -> 65000 | I22: =SUM('Optional Add-Ons Build-Up'!O8, 'Optional Add-Ons Build-Up'!R8) -> 135000
A23: ADD-05 | B23: Additional FQHC | C23: FQHC count exceeds ten | D23: Any scenario | E23: Marginal unit | F23: Onboarding, legal, validation, training, and support | G23: =SUM('Optional Add-Ons Build-Up'!M9, 'Optional Add-Ons Build-Up'!P9) -> 14000 | H23: =SUM('Optional Add-Ons Build-Up'!N9, 'Optional Add-Ons Build-Up'!Q9) -> 31000 | I23: =SUM('Optional Add-Ons Build-Up'!O9, 'Optional Add-Ons Build-Up'!R9) -> 65000
A24: ADD-06 | B24: Additional source-system configuration | C24: More than five distinct configurations or a materially different tenant pattern | D24: Any scenario | E24: Marginal unit | F24: Mapping, interface configuration, testing, and remediation | G24: =SUM('Optional Add-Ons Build-Up'!M10, 'Optional Add-Ons Build-Up'!P10) -> 60000 | H24: =SUM('Optional Add-Ons Build-Up'!N10, 'Optional Add-Ons Build-Up'!Q10) -> 125000 | I24: =SUM('Optional Add-Ons Build-Up'!O10, 'Optional Add-Ons Build-Up'!R10) -> 260000
A25: ADD-07 | B25: Additional production interface | C25: Interface topology exceeds scenario base | D25: Any scenario | E25: Marginal unit | F25: Mapping, interface configuration, testing, and remediation | G25: =SUM('Optional Add-Ons Build-Up'!M11, 'Optional Add-Ons Build-Up'!P11) -> 50000 | H25: =SUM('Optional Add-Ons Build-Up'!N11, 'Optional Add-Ons Build-Up'!Q11) -> 105000 | I25: =SUM('Optional Add-Ons Build-Up'!O11, 'Optional Add-Ons Build-Up'!R11) -> 220000
A26: ADD-08 | B26: Additional remediation cycle | C26: Two base remediation cycles are insufficient | D26: Any scenario | E26: Marginal unit | F26: Vendor, provider, intermediary, and project-management effort | G26: =SUM('Optional Add-Ons Build-Up'!M12, 'Optional Add-Ons Build-Up'!P12) -> 40000 | H26: =SUM('Optional Add-Ons Build-Up'!N12, 'Optional Add-Ons Build-Up'!Q12) -> 95000 | I26: =SUM('Optional Add-Ons Build-Up'!O12, 'Optional Add-Ons Build-Up'!R12) -> 230000
A27: ADD-09 | B27: Six-month operations sensitivity | C27: Schedule permits only six live months or sponsor chooses shorter evidence period | D27: Any scenario | E27: Schedule sensitivity | F27: Reduces recurring support and evaluation evidence period | G27: =SUM('Optional Add-Ons Build-Up'!M13, 'Optional Add-Ons Build-Up'!P13) -> -240000 | H27: =SUM('Optional Add-Ons Build-Up'!N13, 'Optional Add-Ons Build-Up'!Q13) -> -440000 | I27: =SUM('Optional Add-Ons Build-Up'!O13, 'Optional Add-Ons Build-Up'!R13) -> -740000
A28: ADD-10 | B28: Formal security authorization or penetration testing | C28: PHA/intermediary requires ATO-equivalent approval, independent assessment, or new control documentation | D28: Any scenario | E28: Marginal unit | G28: =SUM('Optional Add-Ons Build-Up'!M14, 'Optional Add-Ons Build-Up'!P14) -> 130000 | H28: =SUM('Optional Add-Ons Build-Up'!N14, 'Optional Add-Ons Build-Up'!Q14) -> 330000 | I28: =SUM('Optional Add-Ons Build-Up'!O14, 'Optional Add-Ons Build-Up'!R14) -> 800000
A29: ADD-11 | B29: New environment or software license | C29: Existing environment capacity or licenses are insufficient | D29: Any scenario | E29: Marginal unit | G29: =SUM('Optional Add-Ons Build-Up'!M15, 'Optional Add-Ons Build-Up'!P15) -> 110000 | H29: =SUM('Optional Add-Ons Build-Up'!N15, 'Optional Add-Ons Build-Up'!Q15) -> 260000 | I29: =SUM('Optional Add-Ons Build-Up'!O15, 'Optional Add-Ons Build-Up'!R15) -> 650000
A30: ADD-12 | B30: High-intensity technical assistance | C30: Readiness validation identifies material participant capability gaps | D30: Any scenario | E30: Marginal unit | G30: =SUM('Optional Add-Ons Build-Up'!M16, 'Optional Add-Ons Build-Up'!P16) -> 45000 | H30: =SUM('Optional Add-Ons Build-Up'!N16, 'Optional Add-Ons Build-Up'!Q16) -> 105000 | I30: =SUM('Optional Add-Ons Build-Up'!O16, 'Optional Add-Ons Build-Up'!R16) -> 240000

Sheet Assumptions & Inputs
A1: Model Assumptions and Inputs
A3: Core modeling assumptions
A4: Assumption | B4: Status | C4: Cost Effect | D4: Treatment
A5: Pre-award charter is complete and not funded | B5: Fixed | C5: Reduces funded planning scope | D5: Exclusion
A6: Implementation plan is funded and derived from the charter | B6: Fixed | C6: Adds Month 1 implementation-management effort | D6: Included
A7: Existing FHIR and HL7 v2 endpoints are functioning | B7: Moderate confidence | C7: Avoids greenfield source-interface builds | D7: Base assumption + contingency risk
A8: Architecture and interface documents need minor updates only | B8: High confidence | C8: Limits architecture/design labor | D8: Fixed assumption
A9: Normalization, matching, deduplication, cohort, de-identification, aggregation, trust, monitoring, and analytics capabilities already exist | B9: Moderate confidence | C9: Primary cost-reduction assumption | D9: Base assumption + contingency risk
A10: Existing PHA analytics tool is configured; no new dashboard platform | B10: High confidence | C10: Avoids platform procurement and development | D10: Fixed assumption
A11: PHA receives aggregate and de-identified line-level data | B11: Fixed | C11: Requires two configured output forms | D11: Included
A12: Intermediary executes CMS122; PHA validates results | B12: Provisional | C12: Avoids duplicate measure-engine implementation | D12: Editable assumption
A13: MedicationRequest is required; MedicationDispense only if already available | B13: Fixed | C13: Avoids new pharmacy/payer connection in base | D13: Base scope / add-on if needed
A14: Two remediation cycles are sufficient | B14: Moderate confidence | C14: Caps vendor and participant rework | D14: Base input + per-cycle sensitivity
A15: Participant direct costs and indirect costs are fully reimbursed | B15: Fixed | C15: Increases total to full participant economic cost | D15: Included
A16: NP/prime administration and post-pilot operations are excluded | B16: Fixed | C16: Keeps estimate site-focused and time-limited | D16: Exclusion
A18: Highest-impact unresolved or variable items
A19: Item | B19: Provisional Assumption | C19: Risk if Different | D19: Model Handling
A20: Formal security authorization | B20: No new ATO or penetration test | C20: Material documentation, testing, and schedule increase | D20: Contingency / optional sensitivity
A21: Trust acceptance thresholds | B21: Feasibility-oriented; critical errors resolved, known completeness gaps documented | C21: Stricter thresholds add remediation cycles | D21: Editable assumption
A22: Existing environment availability | B22: Existing test/UAT/production capacity is sufficient | C22: New environments add cloud, deployment, and security costs | D22: Contingency risk
A23: HCCN ability to serve non-FQHC providers | B23: Legally and technically feasible in Scenario 3 | C23: Scenario 3 may need another intermediary or reduced scope | D23: Scenario risk
A24: Broad care-cascade data completeness | B24: Enough existing data to test feasibility | C24: May require added sources or produce limited findings | D24: Contingency risk / limitation
A25: Participant indirect rates | B25: Organization-specific actual rates | C25: Large effect on topline cost | D25: Editable participant inputs in cost build-up
A28: Cost Model Inputs
A29: Blue font / yellow fill = editable provisional input
A30: Input ID | B30: Input | C30: Low | D30: Base | E30: High | F30: Unit | G30: Cost Model Use
A31: IN-01 | B31: Funded pilot sites | C31: 1 | D31: 1 | E31: 1 | F31: sites | G31: Direct formula input
A32: IN-02 | B32: FQHCs | C32: 5 | D32: 10 | E32: 20 | F32: organizations | G32: Direct formula input
A33: IN-03 | B33: Other healthcare organizations | C33: 1 | D33: 2 | E33: 5 | F33: organizations | G33: Direct formula input
A34: IN-04 | B34: All provider organizations | C34: 6 | D34: 12 | E34: 25 | F34: organizations | G34: Derived total; direct formula input
A35: IN-05 | B35: Source configurations | C35: 3 | D35: 5 | E35: 8 | F35: configurations | G35: Direct formula input
A36: IN-06 | B36: Shared FQHC configurations | C36: 1 | D36: 2 | E36: 4 | F36: configurations | G36: Direct formula input
A37: IN-07 | B37: Production interfaces used by selected scenario | C37: =IF(LEFT('Scenario Definitions'!$C$5,1)="1",$C$66,IF(LEFT('Scenario Definitions'!$C$5,1)="2",$C$65,0)) -> 3 | D37: =IF(LEFT('Scenario Definitions'!$C$5,1)="1",$D$66,IF(LEFT('Scenario Definitions'!$C$5,1)="2",$D$65,0)) -> 3 | E37: =IF(LEFT('Scenario Definitions'!$C$5,1)="1",$E$66,IF(LEFT('Scenario Definitions'!$C$5,1)="2",$E$65,0)) -> 5 | F37: interfaces | G37: Scenario lookup used by HIE/HDU interface-related WBS rows
A38: IN-08 | B38: HCCN consolidated export | C38: 1 | D38: 1 | E38: 1 | F38: interface | G38: Direct formula input
A39: IN-09 | B39: PHA receiving interface | C39: 1 | D39: 1 | E39: 1 | F39: interface | G39: Direct formula input
A40: IN-10 | B40: Primary DUAs/DSAs | C40: 3 | D40: 3 | E40: 5 | F40: agreements | G40: Direct formula input
A41: IN-11 | B41: HCCN agreement plus member amendments | C41: 6 | D41: 11 | E41: 21 | F41: legal instruments | G41: Direct formula input
A42: IN-12 | B42: Line-level and aggregate outputs | C42: 2 | D42: 2 | E42: 3 | F42: output types | G42: Direct formula input
A43: IN-13 | B43: PHA surveillance outputs | C43: 1 | D43: 1 | E43: 2 | F43: outputs | G43: Direct formula input
A44: IN-14 | B44: CMS122 measures | C44: 1 | D44: 1 | E44: 2 | F44: measures | G44: Direct formula input
...

Sheet Cost Build-Up
A1: Stage 3 Costable Activity Register
A2: This sheet decomposes the controlling Work Breakdown into activities with distinct cost ownership, scaling logic, scenario applicability, labor mix, non-labor inputs, estimating method, assumptions, and risks.
A4: WBS ID | B4: Parent WBS ID | C4: Organization Group | D4: Lifecycle Workstream | E4: Work Package | F4: Costable Activity | G4: Description | H4: Output or Completion Condition | I4: Accountable Organization | J4: Performing Party | K4: Supporting Parties | L4: Cost-Bearing Party | M4: Funded or In Kind | N4: Scenario Applicability | O4: Cost Model Treatment | P4: Scaling Classification | Q4: Scaling Unit | R4: Quantity Input ID | S4: Formula Type | T4: Lead Labor Category | U4: Supporting Labor Categories | V4: Participant Labor | W4: Vendor Labor | X4: Reviewer or Approver | Y4: Non-Labor Inputs | Z4: Estimating Method | AA4: Benchmark ID | AB4: Complexity Level | AC4: Assumption IDs | AD4: Risk IDs | AE4: Include in Selected Scenario | AF4: Low Quantity | AG4: Base Quantity | AH4: High Quantity | AI4: Low Fixed Hours | AJ4: Base Fixed Hours | AK4: High Fixed Hours | AL4: Low Hours per Unit | AM4: Base Hours per Unit | AN4: High Hours per Unit | AO4: Low Total Hours | AP4: Base Total Hours | AQ4: High Total Hours | AR4: Rate ID | AS4: Loaded Rate | AT4: Low Labor Cost | AU4: Base Labor Cost | AV4: High Labor Cost | AW4: Low Non-Labor Cost | AX4: Base Non-Labor Cost | AY4: High Non-Labor Cost | AZ4: Indirect Rate | BA4: Low Indirect Cost | BB4: Base Indirect Cost | BC4: High Indirect Cost | BD4: Contingency Eligible | BE4: Low Contingency | BF4: Base Contingency | BG4: High Contingency | BH4: Low Total Cost | BI4: Base Total Cost | BJ4: High Total Cost | BK4: BOE Status | BL4: Validation Status | BM4: Source ID | BN4: Adjustment / Notes | BO4: Include 1A | BP4: Include 1B | BQ4: Include 2A | BR4: Include 2B | BS4: Include 3A | BT4: Include 3B | BU4: 1A Low Total | BV4: 1A Base Total | BW4: 1A High Total | BX4: 1B Low Total | BY4: 1B Base Total | BZ4: 1B High Total | CA4: 2A Low Total | CB4: 2A Base Total | CC4: 2A High Total | CD4: 2B Low Total | CE4: 2B Base Total | CF4: 2B High Total | CG4: 3A Low Total | CH4: 3A Base Total | CI4: 3A High Total | CJ4: 3B Low Total | CK4: 3B Base Total | CL4: 3B High Total
A5: WBS-01.01.01 | B5: WBS-01.01 | C5: State PHA | D5: Implementation management | E5: Implementation planning | F5: Develop funded implementation plan | G5: Translate the approved pre-award charter into workstreams, activities, owners, milestones, dependencies, and acceptance gates. | H5: Approved implementation plan with traceability to charter decisions | I5: PHA | J5: PHA project team | K5: Intermediary; HCCN; providers | L5: PHA | M5: Funded | N5: 1A, 1B, 2A, 2B, 3A, 3B | O5: Base common | P5: Fixed per site | Q5: pilot site | R5: IN-01 | S5: Fixed hours | T5: Project manager | U5: Program director; business analyst; project coordinator | V5: PHA staff | W5: None | X5: Pilot governance body | Y5: Travel only if workshop is in person | Z5: Bottom-up labor estimate | AA5: BM-01 | AB5: Moderate | AC5: A01; A12; A13 | AD5: RD-13 | AE5: =IF(ISNUMBER(SEARCH('Scenario Definitions'!$C$5,N5)),1,0) -> 1 | AF5: =IFERROR(VLOOKUP(R5,'Assumptions & Inputs'!$A$31:$F$69,3,FALSE),0) -> 1 | AG5: =IFERROR(VLOOKUP(R5,'Assumptions & Inputs'!$A$31:$F$69,4,FALSE),0) -> 1 | AH5: =IFERROR(VLOOKUP(R5,'Assumptions & Inputs'!$A$31:$F$69,5,FALSE),0) -> 1 | AI5: 90 | AJ5: 120 | AK5: 180 | AL5: 0 | AM5: 0 | AN5: 0 | AO5: =AI5+(AF5*AL5) -> 90 | AP5: =AJ5+(AG5*AM5) -> 120 | AQ5: =AK5+(AH5*AN5) -> 180 | AR5: RT-02 | AS5: =IFERROR(VLOOKUP(AR5,'Assumptions & Inputs'!$A$73:$I$100,9,FALSE),0) -> 120 | AT5: =AO5*AS5 -> 10800 | AU5: =AP5*AS5 -> 14400 | AV5: =AQ5*AS5 -> 21600 | AW5: 3000 | AX5: 8000 | AY5: 18000 | AZ5: =IFERROR(VLOOKUP(C5,'Assumptions & Inputs'!$A$104:$B$107,2,FALSE),0) -> 0.25 | BA5: =AT5*AZ5 -> 2700 | BB5: =AU5*AZ5 -> 3600 | BC5: =AV5*AZ5 -> 5400 | BD5: Yes | BE5: =IF(BD5="Yes",(AT5+AW5)*VLOOKUP("IN-34",'Assumptions & Inputs'!$A$31:$F$69,3,FALSE),0) -> 690 | BF5: =IF(BD5="Yes",(AU5+AX5)*VLOOKUP("IN-34",'Assumptions & Inputs'!$A$31:$F$69,4,FALSE),0) -> 1680 | BG5: =IF(BD5="Yes",(AV5+AY5)*VLOOKUP("IN-34",'Assumptions & Inputs'!$A$31:$F$69,5,FALSE),0) -> 5940 | BH5: =AT5+AW5+BA5+BE5 -> 17190 | BI5: =AU5+AX5+BB5+BF5 -> 27680 | BJ5: =AV5+AY5+BC5+BG5 -> 50940 | BK5: Provisional — expert judgment | BL5: Pending participant validation | BM5: BM-01 | BN5: Provisional Stage 4 assumption; replace with actual rate, quote, or validated benchmark where available. | BO5: =IF(ISNUMBER(SEARCH("1A",N5)),1,0) -> 1 | BP5: =IF(ISNUMBER(SEARCH("1B",N5)),1,0) -> 1 | BQ5: =IF(ISNUMBER(SEARCH("2A",N5)),1,0) -> 1 | BR5: =IF(ISNUMBER(SEARCH("2B",N5)),1,0) -> 1 | BS5: =IF(ISNUMBER(SEARCH("3A",N5)),1,0) -> 1 | BT5: =IF(ISNUMBER(SEARCH("3B",N5)),1,0) -> 1 | BU5: =IF(BO5=1,((AI5+(IF(R5="IN-07",'Assumptions & Inputs'!$C$66,AF5))*AL5)*AS5)+AW5+(((AI5+(IF(R5="IN-07",'Assumptions & Inputs'!$C$66,AF5))*AL5)*AS5)*AZ5)+IF(BD5="Yes",(((AI5+(IF(R5="IN-07",'Assumptions & Inputs'!$C$66,AF5))*AL5)*AS5)+AW5)*VLOOKUP("IN-34",'Assumptions & Inputs'!$A$31:$F$69,3,FALSE),0),0) -> 17190 | BV5: =IF(BO5=1,((AJ5+(IF(R5="IN-07",'Assumptions & Inputs'!$D$66,AG5))*AM5)*AS5)+AX5+(((AJ5+(IF(R5="IN-07",'Assumptions & Inputs'!$D$66,AG5))*AM5)*AS5)*AZ5)+IF(BD5="Yes",(((AJ5+(IF(R5="IN-07",'Assumptions & Inputs'!$D$66,AG5))*AM5)*AS5)+AX5)*VLOOKUP("IN-34",'Assumptions & Inputs'!$A$31:$F$69,4,FALSE),0),0) -> 27680 | BW5: =IF(BO5=1,((AK5+(IF(R5="IN-07",'Assumptions & Inputs'!$E$66,AH5))*AN5)*AS5)+AY5+(((AK5+(IF(R5="IN-07",'Assumptions & Inputs'!$E$66,AH5))*AN5)*AS5)*AZ5)+IF(BD5="Yes",(((AK5+(IF(R5="IN-07",'Assumptions & Inputs'!$E$66,AH5))*AN5)*AS5)+AY5)*VLOOKUP("IN-34",'Assumptions & Inputs'!$A$31:$F$69,5,FALSE),0),0) -> 50940 | BX5: =IF(BP5=1,((AI5+(IF(R5="IN-07",'Assumptions & Inputs'!$C$66,AF5))*AL5)*AS5)+AW5+(((AI5+(IF(R5="IN-07",'Assumptions & Inputs'!$C$66,AF5))*AL5)*AS5)*AZ5)+IF(BD5="Yes",(((AI5+(IF(R5="IN-07",'Assumptions & Inputs'!$C$66,AF5))*AL5)*AS5)+AW5)*VLOOKUP("IN-34",'Assumptions & Inputs'!$A$31:$F$69,3,FALSE),0),0) -> 17190 | BY5: =IF(BP5=1,((AJ5+(IF(R5="IN-07",'Assumptions & Inputs'!$D$66,AG5))*AM5)*AS5)+AX5+(((AJ5+(IF(R5="IN-07",'Assumptions & Inputs'!$D$66,AG5))*AM5)*AS5)*AZ5)+IF(BD5="Yes",(((AJ5+(IF(R5="IN-07",'Assumptions & Inputs'!$D$66,AG5))*AM5)*AS5)+AX5)*VLOOKUP("IN-34",'Assumptions & Inputs'!$A$31:$F$69,4,FALSE),0),0) -> 27680 | BZ5: =IF(BP5=1,((AK5+(IF(R5="IN-07",'Assumptions & Inputs'!$E$66,AH5))*AN5)*AS5)+AY5+(((AK5+(IF(R5="IN-07",'Assumptions & Inputs'!$E$66,AH5))*AN5)*AS5)*AZ5)+IF(BD5="Yes",(((AK5+(IF(R5="IN-07",'Assumptions & Inputs'!$E$66,AH5))*AN5)*AS5)+AY5)*VLOOKUP("IN-34",'Assumptions & Inputs'!$A$31:$F$69,5,FALSE),0),0) -> 50940 | CA5: =IF(BQ5=1,((AI5+(IF(R5="IN-07",'Assumptions & Inputs'!$C$65,AF5))*AL5)*AS5)+AW5+(((AI5+(IF(R5="IN-07",'Assumptions & Inputs'!$C$65,AF5))*AL5)*AS5)*AZ5)+IF(BD5="Yes",(((AI5+(IF(R5="IN-07",'Assumptions & Inputs'!$C$65,AF5))*AL5)*AS5)+AW5)*VLOOKUP("IN-34",'Assumptions & Inputs'!$A$31:$F$69,3,FALSE),0),0) -> 17190 | CB5: =IF(BQ5=1,((AJ5+(IF(R5="IN-07",'Assumptions & Inputs'!$D$65,AG5))*AM5)*AS5)+AX5+(((AJ5+(IF(R5="IN-07",'Assumptions & Inputs'!$D$65,AG5))*AM5)*AS5)*AZ5)+IF(BD5="Yes",(((AJ5+(IF(R5="IN-07",'Assumptions & Inputs'!$D$65,AG5))*AM5)*AS5)+AX5)*VLOOKUP("IN-34",'Assumptions & Inputs'!$A$31:$F$69,4,FALSE),0),0) -> 27680 | CC5: =IF(BQ5=1,((AK5+(IF(R5="IN-07",'Assumptions & Inputs'!$E$65,AH5))*AN5)*AS5)+AY5+(((AK5+(IF(R5="IN-07",'Assumptions & Inputs'!$E$65,AH5))*AN5)*AS5)*AZ5)+IF(BD5="Yes",(((AK5+(IF(R5="IN-07",'Assumptions & Inputs'!$E$65,AH5))*AN5)*AS5)+AY5)*VLOOKUP("IN-34",'Assumptions & Inputs'!$A$31:$F$69,5,FALSE),0),0) -> 50940 | CD5: =IF(BR5=1,((AI5+(IF(R5="IN-07",'Assumptions & Inputs'!$C$65,AF5))*AL5)*AS5)+AW5+(((AI5+(IF(R5="IN-07",'Assumptions & Inputs'!$C$65,AF5))*AL5)*AS5)*AZ5)+IF(BD5="Yes",(((AI5+(IF(R5="IN-07",'Assumptions & Inputs'!$C$65,AF5))*AL5)*AS5)+AW5)*VLOOKUP("IN-34",'Assumptions & Inputs'!$A$31:$F$69,3,FALSE),0),0) -> 17190 | CE5: =IF(BR5=1,((AJ5+(IF(R5="IN-07",'Assumptions & Inputs'!$D$65,AG5))*AM5)*AS5)+AX5+(((AJ5+(IF(R5="IN-07",'Assumptions & Inputs'!$D$65,AG5))*AM5)*AS5)*AZ5)+IF(BD5="Yes",(((AJ5+(IF(R5="IN-07",'Assumptions & Inputs'!$D$65,AG5))*AM5)*AS5)+AX5)*VLOOKUP("IN-34",'Assumptions & Inputs'!$A$31:$F$69,4,FALSE),0),0) -> 27680 | CF5: =IF(BR5=1,((AK5+(IF(R5="IN-07",'Assumptions & Inputs'!$E$65,AH5))*AN5)*AS5)+AY5+(((AK5+(IF(R5="IN-07",'Assumptions & Inputs'!$E$65,AH5))*AN5)*AS5)*AZ5)+IF(BD5="Yes",(((AK5+(IF(R5="IN-07",'Assumptions & Inputs'!$E$65,AH5))*AN5)*AS5)+AY5)*VLOOKUP("IN-34",'Assumptions & Inputs'!$A$31:$F$69,5,FALSE),0),0) -> 50940 | CG5: =IF(BS5=1,((AI5+(IF(R5="IN-07",0,AF5))*AL5)*AS5)+AW5+(((AI5+(IF(R5="IN-07",0,AF5))*AL5)*AS5)*AZ5)+IF(BD5="Yes",(((AI5+(IF(R5="IN-07",0,AF5))*AL5)*AS5)+AW5)*VLOOKUP("IN-34",'Assumptions & Inputs'!$A$31:$F$69,3,FALSE),0),0) -> 17190 | CH5: =IF(BS5=1,((AJ5+(IF(R5="IN-07",0,AG5))*AM5)*AS5)+AX5+(((AJ5+(IF(R5="IN-07",0,AG5))*AM5)*AS5)*AZ5)+IF(BD5="Yes",(((AJ5+(IF(R5="IN-07",0,AG5))*AM5)*AS5)+AX5)*VLOOKUP("IN-34",'Assumptions & Inputs'!$A$31:$F$69,4,FALSE),0),0) -> 27680 | CI5: =IF(BS5=1,((AK5+(IF(R5="IN-07",0,AH5))*AN5)*AS5)+AY5+(((AK5+(IF(R5="IN-07",0,AH5))*AN5)*AS5)*AZ5)+IF(BD5="Yes",(((AK5+(IF(R5="IN-07",0,AH5))*AN5)*AS5)+AY5)*VLOOKUP("IN-34",'Assumptions & Inputs'!$A$31:$F$69,5,FALSE),0),0) -> 50940 | CJ5: =IF(BT5=1,((AI5+(IF(R5="IN-07",0,AF5))*AL5)*AS5)+AW5+(((AI5+(IF(R5="IN-07",0,AF5))*AL5)*AS5)*AZ5)+IF(BD5="Yes",(((AI5+(IF(R5="IN-07",0,AF5))*AL5)*AS5)+AW5)*VLOOKUP("IN-34",'Assumptions & Inputs'!$A$31:$F$69,3,FALSE),0),0) -> 17190 | CK5: =IF(BT5=1,((AJ5+(IF(R5="IN-07",0,AG5))*AM5)*AS5)+AX5+(((AJ5+(IF(R5="IN-07",0,AG5))*AM5)*AS5)*AZ5)+IF(BD5="Yes",(((AJ5+(IF(R5="IN-07",0,AG5))*AM5)*AS5)+AX5)*VLOOKUP("IN-34",'Assumptions & Inputs'!$A$31:$F$69,4,FALSE),0),0) -> 27680 | CL5: =IF(BT5=1,((AK5+(IF(R5="IN-07",0,AH5))*AN5)*AS5)+AY5+(((AK5+(IF(R5="IN-07",0,AH5))*AN5)*AS5)*AZ5)+IF(BD5="Yes",(((AK5+(IF(R5="IN-07",0,AH5))*AN5)*AS5)+AY5)*VLOOKUP("IN-34",'Assumptions & Inputs'!$A$31:$F$69,5,FALSE),0),0) -> 50940
A6: WBS-01.01.02 | B6: WBS-01.01 | C6: State PHA | D6: Implementation management | E6: Implementation planning | F6: Maintain schedule, risks, decisions, and status reporting | G6: Operate the project-control cadence throughout implementation and pilot operations. | H6: Current schedule, RAID log, decision log, and monthly status reports | I6: PHA | J6: PHA project team | K6: Intermediary; HCCN | L6: PHA | M6: Funded | N6: 1A, 1B, 2A, 2B, 3A, 3B | O6: Base common | P6: Recurring | Q6: project month | R6: IN-17 | S6: Monthly hours × operating months | T6: Project manager | U6: Project coordinator; program director | V6: PHA staff | W6: None | X6: Pilot governance body | Y6: Meeting and travel ODCs | Z6: Bottom-up labor estimate | AA6: BM-01 | AB6: Moderate | AC6: A64; A69 | AD6: RD-13 | AE6: =IF(ISNUMBER(SEARCH('Scenario Definitions'!$C$5,N6)),1,0) -> 1 | AF6: =IFERROR(VLOOKUP(R6,'Assumptions & Inputs'!$A$31:$F$69,3,FALSE),0) -> 12 | AG6: =IFERROR(VLOOKUP(R6,'Assumptions & Inputs'!$A$31:$F$69,4,FALSE),0) -> 12 | AH6: =IFERROR(VLOOKUP(R6,'Assumptions & Inputs'!$A$31:$F$69,5,FALSE),0) -> 14 | AI6: 0 | AJ6: 0 | AK6: 0 | AL6: 24 | AM6: 32 | AN6: 48 | AO6: =AI6+(AF6*AL6) -> 288 | AP6: =AJ6+(AG6*AM6) -> 384 | AQ6: =AK6+(AH6*AN6) -> 672 | AR6: RT-02 | AS6: =IFERROR(VLOOKUP(AR6,'Assumptions & Inputs'!$A$73:$I$100,9,FALSE),0) -> 120 | AT6: =AO6*AS6 -> 34560 | AU6: =AP6*AS6 -> 46080 | AV6: =AQ6*AS6 -> 80640 | AW6: 2000 | AX6: 5000 | AY6: 12000 | AZ6: =IFERROR(VLOOKUP(C6,'Assumptions & Inputs'!$A$104:$B$107,2,FALSE),0) -> 0.25 | BA6: =AT6*AZ6 -> 8640 | BB6: =AU6*AZ6 -> 11520 | BC6: =AV6*AZ6 -> 20160 | BD6: Yes | BE6: =IF(BD6="Yes",(AT6+AW6)*VLOOKUP("IN-34",'Assumptions & Inputs'!$A$31:$F$69,3,FALSE),0) -> 1828 | BF6: =IF(BD6="Yes",(AU6+AX6)*VLOOKUP("IN-34",'Assumptions & Inputs'!$A$31:$F$69,4,FALSE),0) -> 3831 | BG6: =IF(BD6="Yes",(AV6+AY6)*VLOOKUP("IN-34",'Assumptions & Inputs'!$A$31:$F$69,5,FALSE),0) -> 13896 | BH6: =AT6+AW6+BA6+BE6 -> 47028 | BI6: =AU6+AX6+BB6+BF6 -> 66431 | BJ6: =AV6+AY6+BC6+BG6 -> 126696 | BK6: Provisional — expert judgment | BL6: Pending participant validation | BM6: BM-01 | BN6: Provisional Stage 4 assumption; replace with actual rate, quote, or validated benchmark where available. | BO6: =IF(ISNUMBER(SEARCH("1A",N6)),1,0) -> 1 | BP6: =IF(ISNUMBER(SEARCH("1B",N6)),1,0) -> 1 | BQ6: =IF(ISNUMBER(SEARCH("2A",N6)),1,0) -> 1 | BR6: =IF(ISNUMBER(SEARCH("2B",N6)),1,0) -> 1 | BS6: =IF(ISNUMBER(SEARCH("3A",N6)),1,0) -> 1 | BT6: =IF(ISNUMBER(SEARCH("3B",N6)),1,0) -> 1 | BU6: =IF(BO6=1,((AI6+(IF(R6="IN-07",'Assumptions & Inputs'!$C$66,AF6))*AL6)*AS6)+AW6+(((AI6+(IF(R6="IN-07",'Assumptions & Inputs'!$C$66,AF6))*AL6)*AS6)*AZ6)+IF(BD6="Yes",(((AI6+(IF(R6="IN-07",'Assumptions & Inputs'!$C$66,AF6))*AL6)*AS6)+AW6)*VLOOKUP("IN-34",'Assumptions & Inputs'!$A$31:$F$69,3,FALSE),0),0) -> 47028 | BV6: =IF(BO6=1,((AJ6+(IF(R6="IN-07",'Assumptions & Inputs'!$D$66,AG6))*AM6)*AS6)+AX6+(((AJ6+(IF(R6="IN-07",'Assumptions & Inputs'!$D$66,AG6))*AM6)*AS6)*AZ6)+IF(BD6="Yes",(((AJ6+(IF(R6="IN-07",'Assumptions & Inputs'!$D$66,AG6))*AM6)*AS6)+AX6)*VLOOKUP("IN-34",'Assumptions & Inputs'!$A$31:$F$69,4,FALSE),0),0) -> 66431 | BW6: =IF(BO6=1,((AK6+(IF(R6="IN-07",'Assumptions & Inputs'!$E$66,AH6))*AN6)*AS6)+AY6+(((AK6+(IF(R6="IN-07",'Assumptions & Inputs'!$E$66,AH6))*AN6)*AS6)*AZ6)+IF(BD6="Yes",(((AK6+(IF(R6="IN-07",'Assumptions & Inputs'!$E$66,AH6))*AN6)*AS6)+AY6)*VLOOKUP("IN-34",'Assumptions & Inputs'!$A$31:$F$69,5,FALSE),0),0) -> 126696 | BX6: =IF(BP6=1,((AI6+(IF(R6="IN-07",'Assumptions & Inputs'!$C$66,AF6))*AL6)*AS6)+AW6+(((AI6+(IF(R6="IN-07",'Assumptions & Inputs'!$C$66,AF6))*AL6)*AS6)*AZ6)+IF(BD6="Yes",(((AI6+(IF(R6="IN-07",'Assumptions & Inputs'!$C$66,AF6))*AL6)*AS6)+AW6)*VLOOKUP("IN-34",'Assumptions & Inputs'!$A$31:$F$69,3,FALSE),0),0) -> 47028 | BY6: =IF(BP6=1,((AJ6+(IF(R6="IN-07",'Assumptions & Inputs'!$D$66,AG6))*AM6)*AS6)+AX6+(((AJ6+(IF(R6="IN-07",'Assumptions & Inputs'!$D$66,AG6))*AM6)*AS6)*AZ6)+IF(BD6="Yes",(((AJ6+(IF(R6="IN-07",'Assumptions & Inputs'!$D$66,AG6))*AM6)*AS6)+AX6)*VLOOKUP("IN-34",'Assumptions & Inputs'!$A$31:$F$69,4,FALSE),0),0) -> 66431 | BZ6: =IF(BP6=1,((AK6+(IF(R6="IN-07",'Assumptions & Inputs'!$E$66,AH6))*AN6)*AS6)+AY6+(((AK6+(IF(R6="IN-07",'Assumptions & Inputs'!$E$66,AH6))*AN6)*AS6)*AZ6)+IF(BD6="Yes",(((AK6+(IF(R6="IN-07",'Assumptions & Inputs'!$E$66,AH6))*AN6)*AS6)+AY6)*VLOOKUP("IN-34",'Assumptions & Inputs'!$A$31:$F$69,5,FALSE),0),0) -> 126696 | CA6: =IF(BQ6=1,((AI6+(IF(R6="IN-07",'Assumptions & Inputs'!$C$65,AF6))*AL6)*AS6)+AW6+(((AI6+(IF(R6="IN-07",'Assumptions & Inputs'!$C$65,AF6))*AL6)*AS6)*AZ6)+IF(BD6="Yes",(((AI6+(IF(R6="IN-07",'Assumptions & Inputs'!$C$65,AF6))*AL6)*AS6)+AW6)*VLOOKUP("IN-34",'Assumptions & Inputs'!$A$31:$F$69,3,FALSE),0),0) -> 47028 | CB6: =IF(BQ6=1,((AJ6+(IF(R6="IN-07",'Assumptions & Inputs'!$D$65,AG6))*AM6)*AS6)+AX6+(((AJ6+(IF(R6="IN-07",'Assumptions & Inputs'!$D$65,AG6))*AM6)*AS6)*AZ6)+IF(BD6="Yes",(((AJ6+(IF(R6="IN-07",'Assumptions & Inputs'!$D$65,AG6))*AM6)*AS6)+AX6)*VLOOKUP("IN-34",'Assumptions & Inputs'!$A$31:$F$69,4,FALSE),0),0) -> 66431 | CC6: =IF(BQ6=1,((AK6+(IF(R6="IN-07",'Assumptions & Inputs'!$E$65,AH6))*AN6)*AS6)+AY6+(((AK6+(IF(R6="IN-07",'Assumptions & Inputs'!$E$65,AH6))*AN6)*AS6)*AZ6)+IF(BD6="Yes",(((AK6+(IF(R6="IN-07",'Assumptions & Inputs'!$E$65,AH6))*AN6)*AS6)+AY6)*VLOOKUP("IN-34",'Assumptions & Inputs'!$A$31:$F$69,5,FALSE),0),0) -> 126696 | CD6: =IF(BR6=1,((AI6+(IF(R6="IN-07",'Assumptions & Inputs'!$C$65,AF6))*AL6)*AS6)+AW6+(((AI6+(IF(R6="IN-07",'Assumptions & Inputs'!$C$65,AF6))*AL6)*AS6)*AZ6)+IF(BD6="Yes",(((AI6+(IF(R6="IN-07",'Assumptions & Inputs'!$C$65,AF6))*AL6)*AS6)+AW6)*VLOOKUP("IN-34",'Assumptions & Inputs'!$A$31:$F$69,3,FALSE),0),0) -> 47028 | CE6: =IF(BR6=1,((AJ6+(IF(R6="IN-07",'Assumptions & Inputs'!$D$65,AG6))*AM6)*AS6)+AX6+(((AJ6+(IF(R6="IN-07",'Assumptions & Inputs'!$D$65,AG6))*AM6)*AS6)*AZ6)+IF(BD6="Yes",(((AJ6+(IF(R6="IN-07",'Assumptions & Inputs'!$D$65,AG6))*AM6)*AS6)+AX6)*VLOOKUP("IN-34",'Assumptions & Inputs'!$A$31:$F$69,4,FALSE),0),0) -> 66431 | CF6: =IF(BR6=1,((AK6+(IF(R6="IN-07",'Assumptions & Inputs'!$E$65,AH6))*AN6)*AS6)+AY6+(((AK6+(IF(R6="IN-07",'Assumptions & Inputs'!$E$65,AH6))*AN6)*AS6)*AZ6)+IF(BD6="Yes",(((AK6+(IF(R6="IN-07",'Assumptions & Inputs'!$E$65,AH6))*AN6)*AS6)+AY6)*VLOOKUP("IN-34",'Assumptions & Inputs'!$A$31:$F$69,5,FALSE),0),0) -> 126696 | CG6: =IF(BS6=1,((AI6+(IF(R6="IN-07",0,AF6))*AL6)*AS6)+AW6+(((AI6+(IF(R6="IN-07",0,AF6))*AL6)*AS6)*AZ6)+IF(BD6="Yes",(((AI6+(IF(R6="IN-07",0,AF6))*AL6)*AS6)+AW6)*VLOOKUP("IN-34",'Assumptions & Inputs'!$A$31:$F$69,3,FALSE),0),0) -> 47028 | CH6: =IF(BS6=1,((AJ6+(IF(R6="IN-07",0,AG6))*AM6)*AS6)+AX6+(((AJ6+(IF(R6="IN-07",0,AG6))*AM6)*AS6)*AZ6)+IF(BD6="Yes",(((AJ6+(IF(R6="IN-07",0,AG6))*AM6)*AS6)+AX6)*VLOOKUP("IN-34",'Assumptions & Inputs'!$A$31:$F$69,4,FALSE),0),0) -> 66431 | CI6: =IF(BS6=1,((AK6+(IF(R6="IN-07",0,AH6))*AN6)*AS6)+AY6+(((AK6+(IF(R6="IN-07",0,AH6))*AN6)*AS6)*AZ6)+IF(BD6="Yes",(((AK6+(IF(R6="IN-07",0,AH6))*AN6)*AS6)+AY6)*VLOOKUP("IN-34",'Assumptions & Inputs'!$A$31:$F$69,5,FALSE),0),0) -> 126696 | CJ6: =IF(BT6=1,((AI6+(IF(R6="IN-07",0,AF6))*AL6)*AS6)+AW6+(((AI6+(IF(R6="IN-07",0,AF6))*AL6)*AS6)*AZ6)+IF(BD6="Yes",(((AI6+(IF(R6="IN-07",0,AF6))*AL6)*AS6)+AW6)*VLOOKUP("IN-34",'Assumptions & Inputs'!$A$31:$F$69,3,FALSE),0),0) -> 47028 | CK6: =IF(BT6=1,((AJ6+(IF(R6="IN-07",0,AG6))*AM6)*AS6)+AX6+(((AJ6+(IF(R6="IN-07",0,AG6))*AM6)*AS6)*AZ6)+IF(BD6="Yes",(((AJ6+(IF(R6="IN-07",0,AG6))*AM6)*AS6)+AX6)*VLOOKUP("IN-34",'Assumptions & Inputs'!$A$31:$F$69,4,FALSE),0),0) -> 66431 | CL6: =IF(BT6=1,((AK6+(IF(R6="IN-07",0,AH6))*AN6)*AS6)+AY6+(((AK6+(IF(R6="IN-07",0,AH6))*AN6)*AS6)*AZ6)+IF(BD6="Yes",(((AK6+(IF(R6="IN-07",0,AH6))*AN6)*AS6)+AY6)*VLOOKUP("IN-34",'Assumptions & Inputs'!$A$31:$F$69,5,FALSE),0),0) -> 126696
A7: WBS-01.02.01 | B7: WBS-01.02 | C7: State PHA | D7: Implementation management | E7: Stakeholder coordination | F7: Facilitate governance and cross-participant decision meetings | G7: Prepare, conduct, and document site-level governance and implementation sessions. | H7: Meeting materials, decisions, action items, and escalations | I7: PHA | J7: PHA project team | K7: All funded participants | L7: PHA | M7: Funded | N7: 1A, 1B, 2A, 2B, 3A, 3B | O7: Base common | P7: Recurring | Q7: meeting cycle | R7: IN-20 | S7: Reporting cycles × hours per report | T7: Project manager | U7: Program director; project coordinator | V7: PHA and participant staff | W7: None | X7: Executive sponsor | Y7: Meeting and travel expenses | Z7: Bottom-up labor estimate | AA7: BM-01 | AB7: Moderate | AC7: A61; A67 | AD7: RD-21 | AE7: =IF(ISNUMBER(SEARCH('Scenario Definitions'!$C$5,N7)),1,0) -> 1 | AF7: =IFERROR(VLOOKUP(R7,'Assumptions & Inputs'!$A$31:$F$69,3,FALSE),0) -> 9 | AG7: =IFERROR(VLOOKUP(R7,'Assumptions & Inputs'!$A$31:$F$69,4,FALSE),0) -> 12 | AH7: =IFERROR(VLOOKUP(R7,'Assumptions & Inputs'!$A$31:$F$69,5,FALSE),0) -> 18 | AI7: 0 | AJ7: 0 | AK7: 0 | AL7: 7.5 | AM7: 10 | AN7: 15 | AO7: =AI7+(AF7*AL7) -> 67.5 | AP7: =AJ7+(AG7*AM7) -> 120 | AQ7: =AK7+(AH7*AN7) -> 270 | AR7: RT-02 | AS7: =IFERROR(VLOOKUP(AR7,'Assumptions & Inputs'!$A$73:$I$100,9,FALSE),0) -> 120 | AT7: =AO7*AS7 -> 8100 | AU7: =AP7*AS7 -> 14400 | AV7: =AQ7*AS7 -> 32400 | AW7: 0 | AX7: 0 | AY7: 0 | AZ7: =IFERROR(VLOOKUP(C7,'Assumptions & Inputs'!$A$104:$B$107,2,FALSE),0) -> 0.25 | BA7: =AT7*AZ7 -> 2025 | BB7: =AU7*AZ7 -> 3600 | BC7: =AV7*AZ7 -> 8100 | BD7: Yes | BE7: =IF(BD7="Yes",(AT7+AW7)*VLOOKUP("IN-34",'Assumptions & Inputs'!$A$31:$F$69,3,FALSE),0) -> 405 | BF7: =IF(BD7="Yes",(AU7+AX7)*VLOOKUP("IN-34",'Assumptions & Inputs'!$A$31:$F$69,4,FALSE),0) -> 1080 | BG7: =IF(BD7="Yes",(AV7+AY7)*VLOOKUP("IN-34",'Assumptions & Inputs'!$A$31:$F$69,5,FALSE),0) -> 4860 | BH7: =AT7+AW7+BA7+BE7 -> 10530 | BI7: =AU7+AX7+BB7+BF7 -> 19080 | BJ7: =AV7+AY7+BC7+BG7 -> 45360 | BK7: Provisional — expert judgment | BL7: Pending participant validation | BM7: BM-01 | BN7: Provisional Stage 4 assumption; replace with actual rate, quote, or validated benchmark where available. | BO7: =IF(ISNUMBER(SEARCH("1A",N7)),1,0) -> 1 | BP7: =IF(ISNUMBER(SEARCH("1B",N7)),1,0) -> 1 | BQ7: =IF(ISNUMBER(SEARCH("2A",N7)),1,0) -> 1 | BR7: =IF(ISNUMBER(SEARCH("2B",N7)),1,0) -> 1 | BS7: =IF(ISNUMBER(SEARCH("3A",N7)),1,0) -> 1 | BT7: =IF(ISNUMBER(SEARCH("3B",N7)),1,0) -> 1 | BU7: =IF(BO7=1,((AI7+(IF(R7="IN-07",'Assumptions & Inputs'!$C$66,AF7))*AL7)*AS7)+AW7+(((AI7+(IF(R7="IN-07",'Assumptions & Inputs'!$C$66,AF7))*AL7)*AS7)*AZ7)+IF(BD7="Yes",(((AI7+(IF(R7="IN-07",'Assumptions & Inputs'!$C$66,AF7))*AL7)*AS7)+AW7)*VLOOKUP("IN-34",'Assumptions & Inputs'!$A$31:$F$69,3,FALSE),0),0) -> 10530 | BV7: =IF(BO7=1,((AJ7+(IF(R7="IN-07",'Assumptions & Inputs'!$D$66,AG7))*AM7)*AS7)+AX7+(((AJ7+(IF(R7="IN-07",'Assumptions & Inputs'!$D$66,AG7))*AM7)*AS7)*AZ7)+IF(BD7="Yes",(((AJ7+(IF(R7="IN-07",'Assumptions & Inputs'!$D$66,AG7))*AM7)*AS7)+AX7)*VLOOKUP("IN-34",'Assumptions & Inputs'!$A$31:$F$69,4,FALSE),0),0) -> 19080 | BW7: =IF(BO7=1,((AK7+(IF(R7="IN-07",'Assumptions & Inputs'!$E$66,AH7))*AN7)*AS7)+AY7+(((AK7+(IF(R7="IN-07",'Assumptions & Inputs'!$E$66,AH7))*AN7)*AS7)*AZ7)+IF(BD7="Yes",(((AK7+(IF(R7="IN-07",'Assumptions & Inputs'!$E$66,AH7))*AN7)*AS7)+AY7)*VLOOKUP("IN-34",'Assumptions & Inputs'!$A$31:$F$69,5,FALSE),0),0) -> 45360 | BX7: =IF(BP7=1,((AI7+(IF(R7="IN-07",'Assumptions & Inputs'!$C$66,AF7))*AL7)*AS7)+AW7+(((AI7+(IF(R7="IN-07",'Assumptions & Inputs'!$C$66,AF7))*AL7)*AS7)*AZ7)+IF(BD7="Yes",(((AI7+(IF(R7="IN-07",'Assumptions & Inputs'!$C$66,AF7))*AL7)*AS7)+AW7)*VLOOKUP("IN-34",'Assumptions & Inputs'!$A$31:$F$69,3,FALSE),0),0) -> 10530 | BY7: =IF(BP7=1,((AJ7+(IF(R7="IN-07",'Assumptions & Inputs'!$D$66,AG7))*AM7)*AS7)+AX7+(((AJ7+(IF(R7="IN-07",'Assumptions & Inputs'!$D$66,AG7))*AM7)*AS7)*AZ7)+IF(BD7="Yes",(((AJ7+(IF(R7="IN-07",'Assumptions & Inputs'!$D$66,AG7))*AM7)*AS7)+AX7)*VLOOKUP("IN-34",'Assumptions & Inputs'!$A$31:$F$69,4,FALSE),0),0) -> 19080 | BZ7: =IF(BP7=1,((AK7+(IF(R7="IN-07",'Assumptions & Inputs'!$E$66,AH7))*AN7)*AS7)+AY7+(((AK7+(IF(R7="IN-07",'Assumptions & Inputs'!$E$66,AH7))*AN7)*AS7)*AZ7)+IF(BD7="Yes",(((AK7+(IF(R7="IN-07",'Assumptions & Inputs'!$E$66,AH7))*AN7)*AS7)+AY7)*VLOOKUP("IN-34",'Assumptions & Inputs'!$A$31:$F$69,5,FALSE),0),0) -> 45360 | CA7: =IF(BQ7=1,((AI7+(IF(R7="IN-07",'Assumptions & Inputs'!$C$65,AF7))*AL7)*AS7)+AW7+(((AI7+(IF(R7="IN-07",'Assumptions & Inputs'!$C$65,AF7))*AL7)*AS7)*AZ7)+IF(BD7="Yes",(((AI7+(IF(R7="IN-07",'Assumptions & Inputs'!$C$65,AF7))*AL7)*AS7)+AW7)*VLOOKUP("IN-34",'Assumptions & Inputs'!$A$31:$F$69,3,FALSE),0),0) -> 10530 | CB7: =IF(BQ7=1,((AJ7+(IF(R7="IN-07",'Assumptions & Inputs'!$D$65,AG7))*AM7)*AS7)+AX7+(((AJ7+(IF(R7="IN-07",'Assumptions & Inputs'!$D$65,AG7))*AM7)*AS7)*AZ7)+IF(BD7="Yes",(((AJ7+(IF(R7="IN-07",'Assumptions & Inputs'!$D$65,AG7))*AM7)*AS7)+AX7)*VLOOKUP("IN-34",'Assumptions & Inputs'!$A$31:$F$69,4,FALSE),0),0) -> 19080 | CC7: =IF(BQ7=1,((AK7+(IF(R7="IN-07",'Assumptions & Inputs'!$E$65,AH7))*AN7)*AS7)+AY7+(((AK7+(IF(R7="IN-07",'Assumptions & Inputs'!$E$65,AH7))*AN7)*AS7)*AZ7)+IF(BD7="Yes",(((AK7+(IF(R7="IN-07",'Assumptions & Inputs'!$E$65,AH7))*AN7)*AS7)+AY7)*VLOOKUP("IN-34",'Assumptions & Inputs'!$A$31:$F$69,5,FALSE),0),0) -> 45360 | CD7: =IF(BR7=1,((AI7+(IF(R7="IN-07",'Assumptions & Inputs'!$C$65,AF7))*AL7)*AS7)+AW7+(((AI7+(IF(R7="IN-07",'Assumptions & Inputs'!$C$65,AF7))*AL7)*AS7)*AZ7)+IF(BD7="Yes",(((AI7+(IF(R7="IN-07",'Assumptions & Inputs'!$C$65,AF7))*AL7)*AS7)+AW7)*VLOOKUP("IN-34",'Assumptions & Inputs'!$A$31:$F$69,3,FALSE),0),0) -> 10530 | CE7: =IF(BR7=1,((AJ7+(IF(R7="IN-07",'Assumptions & Inputs'!$D$65,AG7))*AM7)*AS7)+AX7+(((AJ7+(IF(R7="IN-07",'Assumptions & Inputs'!$D$65,AG7))*AM7)*AS7)*AZ7)+IF(BD7="Yes",(((AJ7+(IF(R7="IN-07",'Assumptions & Inputs'!$D$65,AG7))*AM7)*AS7)+AX7)*VLOOKUP("IN-34",'Assumptions & Inputs'!$A$31:$F$69,4,FALSE),0),0) -> 19080 | CF7: =IF(BR7=1,((AK7+(IF(R7="IN-07",'Assumptions & Inputs'!$E$65,AH7))*AN7)*AS7)+AY7+(((AK7+(IF(R7="IN-07",'Assumptions & Inputs'!$E$65,AH7))*AN7)*AS7)*AZ7)+IF(BD7="Yes",(((AK7+(IF(R7="IN-07",'Assumptions & Inputs'!$E$65,AH7))*AN7)*AS7)+AY7)*VLOOKUP("IN-34",'Assumptions & Inputs'!$A$31:$F$69,5,FALSE),0),0) -> 45360 | CG7: =IF(BS7=1,((AI7+(IF(R7="IN-07",0,AF7))*AL7)*AS7)+AW7+(((AI7+(IF(R7="IN-07",0,AF7))*AL7)*AS7)*AZ7)+IF(BD7="Yes",(((AI7+(IF(R7="IN-07",0,AF7))*AL7)*AS7)+AW7)*VLOOKUP("IN-34",'Assumptions & Inputs'!$A$31:$F$69,3,FALSE),0),0) -> 10530 | CH7: =IF(BS7=1,((AJ7+(IF(R7="IN-07",0,AG7))*AM7)*AS7)+AX7+(((AJ7+(IF(R7="IN-07",0,AG7))*AM7)*AS7)*AZ7)+IF(BD7="Yes",(((AJ7+(IF(R7="IN-07",0,AG7))*AM7)*AS7)+AX7)*VLOOKUP("IN-34",'Assumptions & Inputs'!$A$31:$F$69,4,FALSE),0),0) -> 19080 | CI7: =IF(BS7=1,((AK7+(IF(R7="IN-07",0,AH7))*AN7)*AS7)+AY7+(((AK7+(IF(R7="IN-07",0,AH7))*AN7)*AS7)*AZ7)+IF(BD7="Yes",(((AK7+(IF(R7="IN-07",0,AH7))*AN7)*AS7)+AY7)*VLOOKUP("IN-34",'Assumptions & Inputs'!$A$31:$F$69,5,FALSE),0),0) -> 45360 | CJ7: =IF(BT7=1,((AI7+(IF(R7="IN-07",0,AF7))*AL7)*AS7)+AW7+(((AI7+(IF(R7="IN-07",0,AF7))*AL7)*AS7)*AZ7)+IF(BD7="Yes",(((AI7+(IF(R7="IN-07",0,AF7))*AL7)*AS7)+AW7)*VLOOKUP("IN-34",'Assumptions & Inputs'!$A$31:$F$69,3,FALSE),0),0) -> 10530 | CK7: =IF(BT7=1,((AJ7+(IF(R7="IN-07",0,AG7))*AM7)*AS7)+AX7+(((AJ7+(IF(R7="IN-07",0,AG7))*AM7)*AS7)*AZ7)+IF(BD7="Yes",(((AJ7+(IF(R7="IN-07",0,AG7))*AM7)*AS7)+AX7)*VLOOKUP("IN-34",'Assumptions & Inputs'!$A$31:$F$69,4,FALSE),0),0) -> 19080 | CL7: =IF(BT7=1,((AK7+(IF(R7="IN-07",0,AH7))*AN7)*AS7)+AY7+(((AK7+(IF(R7="IN-07",0,AH7))*AN7)*AS7)*AZ7)+IF(BD7="Yes",(((AK7+(IF(R7="IN-07",0,AH7))*AN7)*AS7)+AY7)*VLOOKUP("IN-34",'Assumptions & Inputs'!$A$31:$F$69,5,FALSE),0),0) -> 45360
A8: WBS-01.03.01 | B8: WBS-01.03 | C8: State PHA | D8: Governance, legal, privacy, and security | E8: Governance activation | F8: Operationalize governance and decision rights | G8: Activate decision, escalation, change-control, access-approval, and issue-resolution processes already defined in the charter. | H8: Operating governance calendar and decision-rights matrix | I8: PHA | J8: PHA governance lead | K8: Intermediary; HCCN; providers | L8: PHA | M8: Funded | N8: 1A, 1B, 2A, 2B, 3A, 3B | O8: Base common | P8: Fixed per site | Q8: pilot site | R8: IN-01 | S8: Fixed hours | T8: Governance specialist | U8: Project manager; legal counsel; privacy officer | V8: PHA staff | W8: None | X8: Executive sponsor | Y8: None material | Z8: Bottom-up labor estimate | AA8: BM-02 | AB8: Moderate | AC8: A67 | AD8: RD-24 | AE8: =IF(ISNUMBER(SEARCH('Scenario Definitions'!$C$5,N8)),1,0) -> 1 | AF8: =IFERROR(VLOOKUP(R8,'Assumptions & Inputs'!$A$31:$F$69,3,FALSE),0) -> 1 | AG8: =IFERROR(VLOOKUP(R8,'Assumptions & Inputs'!$A$31:$F$69,4,FALSE),0) -> 1 | AH8: =IFERROR(VLOOKUP(R8,'Assumptions & Inputs'!$A$31:$F$69,5,FALSE),0) -> 1 | AI8: 48 | AJ8: 64 | AK8: 96 | AL8: 0 | AM8: 0 | AN8: 0 | AO8: =AI8+(AF8*AL8) -> 48 | AP8: =AJ8+(AG8*AM8) -> 64 | AQ8: =AK8+(AH8*AN8) -> 96 | AR8: RT-05 | AS8: =IFERROR(VLOOKUP(AR8,'Assumptions & Inputs'!$A$73:$I$100,9,FALSE),0) -> 95 | AT8: =AO8*AS8 -> 4560 | AU8: =AP8*AS8 -> 6080 | AV8: =AQ8*AS8 -> 9120 | AW8: 0 | AX8: 0 | AY8: 0 | AZ8: =IFERROR(VLOOKUP(C8,'Assumptions & Inputs'!$A$104:$B$107,2,FALSE),0) -> 0.25 | BA8: =AT8*AZ8 -> 1140 | BB8: =AU8*AZ8 -> 1520 | BC8: =AV8*AZ8 -> 2280 | BD8: Yes | BE8: =IF(BD8="Yes",(AT8+AW8)*VLOOKUP("IN-34",'Assumptions & Inputs'!$A$31:$F$69,3,FALSE),0) -> 228 | BF8: =IF(BD8="Yes",(AU8+AX8)*VLOOKUP("IN-34",'Assumptions & Inputs'!$A$31:$F$69,4,FALSE),0) -> 456 | BG8: =IF(BD8="Yes",(AV8+AY8)*VLOOKUP("IN-34",'Assumptions & Inputs'!$A$31:$F$69,5,FALSE),0) -> 1368 | BH8: =AT8+AW8+BA8+BE8 -> 5928 | BI8: =AU8+AX8+BB8+BF8 -> 8056 | BJ8: =AV8+AY8+BC8+BG8 -> 12768 | BK8: Provisional — expert judgment | BL8: Pending participant validation | BM8: BM-02 | BN8: Provisional Stage 4 assumption; replace with actual rate, quote, or validated benchmark where available. | BO8: =IF(ISNUMBER(SEARCH("1A",N8)),1,0) -> 1 | BP8: =IF(ISNUMBER(SEARCH("1B",N8)),1,0) -> 1 | BQ8: =IF(ISNUMBER(SEARCH("2A",N8)),1,0) -> 1 | BR8: =IF(ISNUMBER(SEARCH("2B",N8)),1,0) -> 1 | BS8: =IF(ISNUMBER(SEARCH("3A",N8)),1,0) -> 1 | BT8: =IF(ISNUMBER(SEARCH("3B",N8)),1,0) -> 1 | BU8: =IF(BO8=1,((AI8+(IF(R8="IN-07",'Assumptions & Inputs'!$C$66,AF8))*AL8)*AS8)+AW8+(((AI8+(IF(R8="IN-07",'Assumptions & Inputs'!$C$66,AF8))*AL8)*AS8)*AZ8)+IF(BD8="Yes",(((AI8+(IF(R8="IN-07",'Assumptions & Inputs'!$C$66,AF8))*AL8)*AS8)+AW8)*VLOOKUP("IN-34",'Assumptions & Inputs'!$A$31:$F$69,3,FALSE),0),0) -> 5928 | BV8: =IF(BO8=1,((AJ8+(IF(R8="IN-07",'Assumptions & Inputs'!$D$66,AG8))*AM8)*AS8)+AX8+(((AJ8+(IF(R8="IN-07",'Assumptions & Inputs'!$D$66,AG8))*AM8)*AS8)*AZ8)+IF(BD8="Yes",(((AJ8+(IF(R8="IN-07",'Assumptions & Inputs'!$D$66,AG8))*AM8)*AS8)+AX8)*VLOOKUP("IN-34",'Assumptions & Inputs'!$A$31:$F$69,4,FALSE),0),0) -> 8056 | BW8: =IF(BO8=1,((AK8+(IF(R8="IN-07",'Assumptions & Inputs'!$E$66,AH8))*AN8)*AS8)+AY8+(((AK8+(IF(R8="IN-07",'Assumptions & Inputs'!$E$66,AH8))*AN8)*AS8)*AZ8)+IF(BD8="Yes",(((AK8+(IF(R8="IN-07",'Assumptions & Inputs'!$E$66,AH8))*AN8)*AS8)+AY8)*VLOOKUP("IN-34",'Assumptions & Inputs'!$A$31:$F$69,5,FALSE),0),0) -> 12768 | BX8: =IF(BP8=1,((AI8+(IF(R8="IN-07",'Assumptions & Inputs'!$C$66,AF8))*AL8)*AS8)+AW8+(((AI8+(IF(R8="IN-07",'Assumptions & Inputs'!$C$66,AF8))*AL8)*AS8)*AZ8)+IF(BD8="Yes",(((AI8+(IF(R8="IN-07",'Assumptions & Inputs'!$C$66,AF8))*AL8)*AS8)+AW8)*VLOOKUP("IN-34",'Assumptions & Inputs'!$A$31:$F$69,3,FALSE),0),0) -> 5928 | BY8: =IF(BP8=1,((AJ8+(IF(R8="IN-07",'Assumptions & Inputs'!$D$66,AG8))*AM8)*AS8)+AX8+(((AJ8+(IF(R8="IN-07",'Assumptions & Inputs'!$D$66,AG8))*AM8)*AS8)*AZ8)+IF(BD8="Yes",(((AJ8+(IF(R8="IN-07",'Assumptions & Inputs'!$D$66,AG8))*AM8)*AS8)+AX8)*VLOOKUP("IN-34",'Assumptions & Inputs'!$A$31:$F$69,4,FALSE),0),0) -> 8056 | BZ8: =IF(BP8=1,((AK8+(IF(R8="IN-07",'Assumptions & Inputs'!$E$66,AH8))*AN8)*AS8)+AY8+(((AK8+(IF(R8="IN-07",'Assumptions & Inputs'!$E$66,AH8))*AN8)*AS8)*AZ8)+IF(BD8="Yes",(((AK8+(IF(R8="IN-07",'Assumptions & Inputs'!$E$66,AH8))*AN8)*AS8)+AY8)*VLOOKUP("IN-34",'Assumptions & Inputs'!$A$31:$F$69,5,FALSE),0),0) -> 12768 | CA8: =IF(BQ8=1,((AI8+(IF(R8="IN-07",'Assumptions & Inputs'!$C$65,AF8))*AL8)*AS8)+AW8+(((AI8+(IF(R8="IN-07",'Assumptions & Inputs'!$C$65,AF8))*AL8)*AS8)*AZ8)+IF(BD8="Yes",(((AI8+(IF(R8="IN-07",'Assumptions & Inputs'!$C$65,AF8))*AL8)*AS8)+AW8)*VLOOKUP("IN-34",'Assumptions & Inputs'!$A$31:$F$69,3,FALSE),0),0) -> 5928 | CB8: =IF(BQ8=1,((AJ8+(IF(R8="IN-07",'Assumptions & Inputs'!$D$65,AG8))*AM8)*AS8)+AX8+(((AJ8+(IF(R8="IN-07",'Assumptions & Inputs'!$D$65,AG8))*AM8)*AS8)*AZ8)+IF(BD8="Yes",(((AJ8+(IF(R8="IN-07",'Assumptions & Inputs'!$D$65,AG8))*AM8)*AS8)+AX8)*VLOOKUP("IN-34",'Assumptions & Inputs'!$A$31:$F$69,4,FALSE),0),0) -> 8056 | CC8: =IF(BQ8=1,((AK8+(IF(R8="IN-07",'Assumptions & Inputs'!$E$65,AH8))*AN8)*AS8)+AY8+(((AK8+(IF(R8="IN-07",'Assumptions & Inputs'!$E$65,AH8))*AN8)*AS8)*AZ8)+IF(BD8="Yes",(((AK8+(IF(R8="IN-07",'Assumptions & Inputs'!$E$65,AH8))*AN8)*AS8)+AY8)*VLOOKUP("IN-34",'Assumptions & Inputs'!$A$31:$F$69,5,FALSE),0),0) -> 12768 | CD8: =IF(BR8=1,((AI8+(IF(R8="IN-07",'Assumptions & Inputs'!$C$65,AF8))*AL8)*AS8)+AW8+(((AI8+(IF(R8="IN-07",'Assumptions & Inputs'!$C$65,AF8))*AL8)*AS8)*AZ8)+IF(BD8="Yes",(((AI8+(IF(R8="IN-07",'Assumptions & Inputs'!$C$65,AF8))*AL8)*AS8)+AW8)*VLOOKUP("IN-34",'Assumptions & Inputs'!$A$31:$F$69,3,FALSE),0),0) -> 5928 | CE8: =IF(BR8=1,((AJ8+(IF(R8="IN-07",'Assumptions & Inputs'!$D$65,AG8))*AM8)*AS8)+AX8+(((AJ8+(IF(R8="IN-07",'Assumptions & Inputs'!$D$65,AG8))*AM8)*AS8)*AZ8)+IF(BD8="Yes",(((AJ8+(IF(R8="IN-07",'Assumptions & Inputs'!$D$65,AG8))*AM8)*AS8)+AX8)*VLOOKUP("IN-34",'Assumptions & Inputs'!$A$31:$F$69,4,FALSE),0),0) -> 8056 | CF8: =IF(BR8=1,((AK8+(IF(R8="IN-07",'Assumptions & Inputs'!$E$65,AH8))*AN8)*AS8)+AY8+(((AK8+(IF(R8="IN-07",'Assumptions & Inputs'!$E$65,AH8))*AN8)*AS8)*AZ8)+IF(BD8="Yes",(((AK8+(IF(R8="IN-07",'Assumptions & Inputs'!$E$65,AH8))*AN8)*AS8)+AY8)*VLOOKUP("IN-34",'Assumptions & Inputs'!$A$31:$F$69,5,FALSE),0),0) -> 12768 | CG8: =IF(BS8=1,((AI8+(IF(R8="IN-07",0,AF8))*AL8)*AS8)+AW8+(((AI8+(IF(R8="IN-07",0,AF8))*AL8)*AS8)*AZ8)+IF(BD8="Yes",(((AI8+(IF(R8="IN-07",0,AF8))*AL8)*AS8)+AW8)*VLOOKUP("IN-34",'Assumptions & Inputs'!$A$31:$F$69,3,FALSE),0),0) -> 5928 | CH8: =IF(BS8=1,((AJ8+(IF(R8="IN-07",0,AG8))*AM8)*AS8)+AX8+(((AJ8+(IF(R8="IN-07",0,AG8))*AM8)*AS8)*AZ8)+IF(BD8="Yes",(((AJ8+(IF(R8="IN-07",0,AG8))*AM8)*AS8)+AX8)*VLOOKUP("IN-34",'Assumptions & Inputs'!$A$31:$F$69,4,FALSE),0),0) -> 8056 | CI8: =IF(BS8=1,((AK8+(IF(R8="IN-07",0,AH8))*AN8)*AS8)+AY8+(((AK8+(IF(R8="IN-07",0,AH8))*AN8)*AS8)*AZ8)+IF(BD8="Yes",(((AK8+(IF(R8="IN-07",0,AH8))*AN8)*AS8)+AY8)*VLOOKUP("IN-34",'Assumptions & Inputs'!$A$31:$F$69,5,FALSE),0),0) -> 12768 | CJ8: =IF(BT8=1,((AI8+(IF(R8="IN-07",0,AF8))*AL8)*AS8)+AW8+(((AI8+(IF(R8="IN-07",0,AF8))*AL8)*AS8)*AZ8)+IF(BD8="Yes",(((AI8+(IF(R8="IN-07",0,AF8))*AL8)*AS8)+AW8)*VLOOKUP("IN-34",'Assumptions & Inputs'!$A$31:$F$69,3,FALSE),0),0) -> 5928 | CK8: =IF(BT8=1,((AJ8+(IF(R8="IN-07",0,AG8))*AM8)*AS8)+AX8+(((AJ8+(IF(R8="IN-07",0,AG8))*AM8)*AS8)*AZ8)+IF(BD8="Yes",(((AJ8+(IF(R8="IN-07",0,AG8))*AM8)*AS8)+AX8)*VLOOKUP("IN-34",'Assumptions & Inputs'!$A$31:$F$69,4,FALSE),0),0) -> 8056 | CL8: =IF(BT8=1,((AK8+(IF(R8="IN-07",0,AH8))*AN8)*AS8)+AY8+(((AK8+(IF(R8="IN-07",0,AH8))*AN8)*AS8)*AZ8)+IF(BD8="Yes",(((AK8+(IF(R8="IN-07",0,AH8))*AN8)*AS8)+AY8)*VLOOKUP("IN-34",'Assumptions & Inputs'!$A$31:$F$69,5,FALSE),0),0) -> 12768
